<?xml version="1.0" ?>
<sdf version="1.5">
  <model name="arm">
    <link name="base">
     <pose>0 0 0.05 0 0 0</pose>
      <visual name="visual">
        <geometry>
          <cylinder>
            <radius>.5</radius>
            <length>.1</length>
          </cylinder>
        </geometry>
      </visual>

      <collision name="collision">
        <geometry>
         <cylinder>
            <radius>.5</radius>
            <length>.1</length>
          </cylinder>
        </geometry>
      </collision>
    </link>

    <link name="arm_1">
      <pose>0 0 0.125 0 0 0</pose>
      <visual name="visual">
        <geometry>
          <cylinder>
            <radius>.1</radius>
            <length>0.05</length>
          </cylinder>
        </geometry>
      </visual>
      <collision name="c1">
      <geometry>
          <cylinder>
            <radius>.1</radius>
            <length>0.05</length>
          </cylinder>
        </geometry>
      </collision>



</link>


<link name="arm_2">
      <pose>0 0 1.15 0 0 0</pose>
      <visual name="visual">
        <geometry>
          <cylinder>
            <radius>.1</radius>
            <length>2</length>
          </cylinder>
        </geometry>
      </visual>
      <collision name="c2">
      <geometry>
          <cylinder>
            <radius>.1</radius>
            <length>0.05</length>
          </cylinder>
        </geometry>
      </collision>

</link>



    <joint name="base_arm_1" type="revolute">
      <parent>base</parent>
      <child>arm_1</child>
      <pose>0 0 -0.025 0 0 0</pose>
      <axis>
        <xyz>0 0 1</xyz>
      </axis>
    </joint>


    <joint name="arm_1_arm_2" type="revolute">
      <parent>arm_1</parent>
      <child>arm_2</child>
      <pose>0 0 -1 0 0 0</pose>
      <axis>
        <xyz>1 0 0</xyz>
      </axis>
    </joint>

    

      
  </model>
</sdf>
